<?xml version="1.0" encoding="utf-8"?>
<robot name="MinimalRobot">
  <joint name="base_joint" type="fixed">
    <origin rpy="0 0 0" xyz="0 0 0"/>
    <parent link="world"/>
    <child link="base_link"/>
  </joint>
  <link name="base_link">
    <collision>
      <origin rpy="0 0 0" xyz="0 0 0"/>
      <geometry>
        <cylinder length="1" radius="0.1"/>
      </geometry>
    </collision>
  </link>
  <joint name="joint1" type="revolute">
    <origin rpy="-1.57079632679 0 0" xyz="0 0 0.2"/>
    <parent link="base_link"/>
    <child link="link1"/>
    <limit effort="0.1" lower="-3.14159265359" upper="3.14159265359" velocity="0.2"/>
  </joint>
  <link name="link1">
    <collision>
      <origin rpy="0 0 0" xyz="0 0 0"/>
      <geometry>
        <cylinder length="1" radius="0.1"/>
      </geometry>
    </collision>
  </link>
  <joint name="joint2" type="revolute">
    <origin rpy="1.57079632679 0 0" xyz="0 0 0.9"/>
    <parent link="link1"/>
    <child link="link2"/>
    <limit effort="0.1" lower="-3.14159265359" upper="3.14159265359" velocity="0.2"/>
  </joint>
  <link name="link2">
    <collision>
      <origin rpy="0 0 0" xyz="0 0 0"/>
      <geometry>
        <cylinder length="1" radius="0.1"/>
      </geometry>
    </collision>
  </link>
  <joint name="tool_joint" type="fixed">
    <origin rpy="0 0 0" xyz="0 0 1"/>
    <parent link="link2"/>
    <child link="tool_link"/>
  </joint>
  
  <ros2_control name="TestSystemComponent" type="system">
    <hardware>
      <plugin>packman_hardware/SystemInterface</plugin>
      <param name="can_device">vcan0</param>
    </hardware>
    <joint name="joint1">
      <command_interface name="velocity"/>
      <state_interface name="velocity"/>
    </joint>
    <joint name="joint2">
      <command_interface name="velocity"/>
      <state_interface name="velocity"/>
    </joint>
  </ros2_control>
</robot>